import java.util.concurrent.ExecutionException;

public class TesteSonar {

	public static void main(String[] args) throws Exception {

//		Valida();

//		try {
//			doSomethingWhichThrowsException();
//			System.out.println("OK"); // incorrect "OK" message is printed
//		} catch (Exception e) {
//			System.out.println("ERROR"); // this message is not shown
//			e.printStackTrace();
//		}
//	}
//
//	public static void doSomethingWhichThrowsException() throws Exception {
//		
//		try { 
//			System.out.println("try1");
//			try {
//				System.out.println("try2");
//			}catch (Exception e) {
//				System.out.println("catch2");
//			}finally {
//				System.out.println("finaly");
//			}
//		
//		}catch (Exception e) {
//			System.out.println("catch1");
//		}
//		System.out.println("passei aqui");
//	}

//	public static void Valida() throws CloseException {
//		try {
//			for (int i = 0; i < 3; i++) {
//				System.out.println("try1");
//				throw(new Exception());
//			}
//			
//		}catch (Exception e) {
//			System.out.println(e);
//		}finally {
//			int i = 3;
//			if(i == 3) {
//				throw (new CloseException());
//			}
//		}
//		
//	}
}}
